Traceback (most recent call last):
  File "C:\Users\VB\Documents\GitHub\TPRO\main.py", line 19, in <module>
    student = Listener(repo)
  File "C:\Users\VB\Documents\GitHub\TPRO\logic\listener.py", line 13, in __init__
    self.process_events(repo.get_issues_events())
  File "C:\Users\VB\Documents\GitHub\TPRO\logic\listener.py", line 34, in process_events
    EV.process(event)
  File "C:\Users\VB\Documents\GitHub\TPRO\logic\event.py", line 483, in process
    EVENTS[event.type](event)
  File "C:\Users\VB\Documents\GitHub\TPRO\logic\event.py", line 223, in review_requested
    check_files(pull)
  File "C:\Users\VB\Documents\GitHub\TPRO\logic\event.py", line 307, in check_files
    check_code(pull, file)
  File "C:\Users\VB\Documents\GitHub\TPRO\logic\event.py", line 190, in check_code
    pull.create_review_comment(
  File "C:\Users\VB\AppData\Local\Programs\Python\Python38-32\lib\site-packages\github\PullRequest.py", line 414, in create_review_comment
    headers, data = self._requester.requestJsonAndCheck(
  File "C:\Users\VB\AppData\Local\Programs\Python\Python38-32\lib\site-packages\github\Requester.py", line 317, in requestJsonAndCheck
    return self.__check(
  File "C:\Users\VB\AppData\Local\Programs\Python\Python38-32\lib\site-packages\github\Requester.py", line 342, in __check
    raise self.__createException(status, responseHeaders, output)
github.GithubException.GithubException: 422 {"message": "Validation Failed", "errors": [{"resource": "PullRequestReviewComment", "code": "invalid", "field": "position"}], "documentation_url": "https://docs.github.com/rest/reference/pulls#create-a-review-comment-for-a-pull-request"}
