Traceback (most recent call last):
  File "C:\Users\VB\Documents\GitHub\TPRO\main.py", line 19, in <module>
    student = Listener(repo)
  File "C:\Users\VB\Documents\GitHub\TPRO\logic\listener.py", line 22, in __init__
    self.process_events(repo.get_issues_events())
  File "C:\Users\VB\Documents\GitHub\TPRO\logic\listener.py", line 31, in process_events
    EV.process(event)
  File "C:\Users\VB\Documents\GitHub\TPRO\logic\event.py", line 343, in process
    else:
  File "C:\Users\VB\Documents\GitHub\TPRO\logic\event.py", line 110, in review_requested
    or 'Elite' in [t.name for t in review_requests[1]]:
  File "C:\Users\VB\Documents\GitHub\TPRO\logic\event.py", line 102, in check_reviewrs
    if len(unreviewers) > 0:
  File "C:\Users\VB\AppData\Local\Programs\Python\Python38-32\lib\site-packages\github\PullRequest.py", line 519, in create_review_request
    headers, data = self._requester.requestJsonAndCheck(
  File "C:\Users\VB\AppData\Local\Programs\Python\Python38-32\lib\site-packages\github\Requester.py", line 317, in requestJsonAndCheck
    return self.__check(
  File "C:\Users\VB\AppData\Local\Programs\Python\Python38-32\lib\site-packages\github\Requester.py", line 342, in __check
    raise self.__createException(status, responseHeaders, output)
github.GithubException.GithubException: 422 {"message": "Review cannot be requested from pull request author.", "documentation_url": "https://docs.github.com/rest/reference/pulls#request-reviewers-for-a-pull-request"}
