Traceback (most recent call last):
  File "C:\Users\VB\AppData\Local\Programs\Python\Python38-32\lib\site-packages\urllib3\connectionpool.py", line 426, in _make_request
    six.raise_from(e, None)
  File "<string>", line 3, in raise_from
  File "C:\Users\VB\AppData\Local\Programs\Python\Python38-32\lib\site-packages\urllib3\connectionpool.py", line 421, in _make_request
    httplib_response = conn.getresponse()
  File "C:\Users\VB\AppData\Local\Programs\Python\Python38-32\lib\http\client.py", line 1347, in getresponse
    response.begin()
  File "C:\Users\VB\AppData\Local\Programs\Python\Python38-32\lib\http\client.py", line 307, in begin
    version, status, reason = self._read_status()
  File "C:\Users\VB\AppData\Local\Programs\Python\Python38-32\lib\http\client.py", line 268, in _read_status
    line = str(self.fp.readline(_MAXLINE + 1), "iso-8859-1")
  File "C:\Users\VB\AppData\Local\Programs\Python\Python38-32\lib\socket.py", line 669, in readinto
    return self._sock.recv_into(b)
  File "C:\Users\VB\AppData\Local\Programs\Python\Python38-32\lib\ssl.py", line 1241, in recv_into
    return self.read(nbytes, buffer)
  File "C:\Users\VB\AppData\Local\Programs\Python\Python38-32\lib\ssl.py", line 1099, in read
    return self._sslobj.read(len, buffer)
socket.timeout: The read operation timed out

During handling of the above exception, another exception occurred:

Traceback (most recent call last):
  File "C:\Users\VB\AppData\Local\Programs\Python\Python38-32\lib\site-packages\requests\adapters.py", line 439, in send
    resp = conn.urlopen(
  File "C:\Users\VB\AppData\Local\Programs\Python\Python38-32\lib\site-packages\urllib3\connectionpool.py", line 726, in urlopen
    retries = retries.increment(
  File "C:\Users\VB\AppData\Local\Programs\Python\Python38-32\lib\site-packages\urllib3\util\retry.py", line 403, in increment
    raise six.reraise(type(error), error, _stacktrace)
  File "C:\Users\VB\AppData\Local\Programs\Python\Python38-32\lib\site-packages\urllib3\packages\six.py", line 735, in reraise
    raise value
  File "C:\Users\VB\AppData\Local\Programs\Python\Python38-32\lib\site-packages\urllib3\connectionpool.py", line 670, in urlopen
    httplib_response = self._make_request(
  File "C:\Users\VB\AppData\Local\Programs\Python\Python38-32\lib\site-packages\urllib3\connectionpool.py", line 428, in _make_request
    self._raise_timeout(err=e, url=url, timeout_value=read_timeout)
  File "C:\Users\VB\AppData\Local\Programs\Python\Python38-32\lib\site-packages\urllib3\connectionpool.py", line 335, in _raise_timeout
    raise ReadTimeoutError(
urllib3.exceptions.ReadTimeoutError: HTTPSConnectionPool(host='api.github.com', port=443): Read timed out. (read timeout=15)

During handling of the above exception, another exception occurred:

Traceback (most recent call last):
  File "C:\Users\VB\Documents\GitHub\TPRO\main.py", line 19, in <module>
    student = Listener(repo)
  File "C:\Users\VB\Documents\GitHub\TPRO\logic\listener.py", line 17, in __init__
    trpo_repo.check_issues()
  File "C:\Users\VB\Documents\GitHub\TPRO\logic\repository.py", line 147, in check_issues
    issue = self.get_issue_by_title_ot_create(
  File "C:\Users\VB\Documents\GitHub\TPRO\logic\repository.py", line 42, in get_issue_by_title_ot_create
    for issue in self.repo.get_issues(state='open'):
  File "C:\Users\VB\AppData\Local\Programs\Python\Python38-32\lib\site-packages\github\PaginatedList.py", line 59, in __iter__
    newElements = self._grow()
  File "C:\Users\VB\AppData\Local\Programs\Python\Python38-32\lib\site-packages\github\PaginatedList.py", line 71, in _grow
    newElements = self._fetchNextPage()
  File "C:\Users\VB\AppData\Local\Programs\Python\Python38-32\lib\site-packages\github\PaginatedList.py", line 203, in _fetchNextPage
    headers, data = self.__requester.requestJsonAndCheck(
  File "C:\Users\VB\AppData\Local\Programs\Python\Python38-32\lib\site-packages\github\Requester.py", line 318, in requestJsonAndCheck
    *self.requestJson(
  File "C:\Users\VB\AppData\Local\Programs\Python\Python38-32\lib\site-packages\github\Requester.py", line 410, in requestJson
    return self.__requestEncode(cnx, verb, url, parameters, headers, input, encode)
  File "C:\Users\VB\AppData\Local\Programs\Python\Python38-32\lib\site-packages\github\Requester.py", line 486, in __requestEncode
    status, responseHeaders, output = self.__requestRaw(
  File "C:\Users\VB\AppData\Local\Programs\Python\Python38-32\lib\site-packages\github\Requester.py", line 513, in __requestRaw
    response = cnx.getresponse()
  File "C:\Users\VB\AppData\Local\Programs\Python\Python38-32\lib\site-packages\github\Requester.py", line 110, in getresponse
    r = verb(
  File "C:\Users\VB\AppData\Local\Programs\Python\Python38-32\lib\site-packages\requests\sessions.py", line 543, in get
    return self.request('GET', url, **kwargs)
  File "C:\Users\VB\AppData\Local\Programs\Python\Python38-32\lib\site-packages\requests\sessions.py", line 530, in request
    resp = self.send(prep, **send_kwargs)
  File "C:\Users\VB\AppData\Local\Programs\Python\Python38-32\lib\site-packages\requests\sessions.py", line 643, in send
    r = adapter.send(request, **kwargs)
  File "C:\Users\VB\AppData\Local\Programs\Python\Python38-32\lib\site-packages\requests\adapters.py", line 529, in send
    raise ReadTimeout(e, request=request)
requests.exceptions.ReadTimeout: HTTPSConnectionPool(host='api.github.com', port=443): Read timed out. (read timeout=15)
